<?xml version="1.0" encoding="UTF-8"?>
<testng-results skipped="0" failed="1" total="2" passed="1">
  <reporter-output>
  </reporter-output>
  <suite name="Default suite" duration-ms="187" started-at="2014-06-18T03:47:12Z" finished-at="2014-06-18T03:47:12Z">
    <groups>
    </groups>
    <test name="Default test" duration-ms="187" started-at="2014-06-18T03:47:12Z" finished-at="2014-06-18T03:47:12Z">
      <class name="tubesRkppl.testNG.KelasA">
        <test-method status="PASS" signature="beforeTest()[pri:0, instance:tubesRkppl.testNG.KelasA@1aa261b]" name="beforeTest" is-config="true" duration-ms="75" started-at="2014-06-18T10:47:12Z" finished-at="2014-06-18T10:47:12Z">
          <reporter-output>
          </reporter-output>
        </test-method> <!-- beforeTest -->
        <test-method status="PASS" signature="test1()[pri:0, instance:tubesRkppl.testNG.KelasA@1aa261b]" name="test1" duration-ms="43" started-at="2014-06-18T10:47:12Z" finished-at="2014-06-18T10:47:12Z">
          <reporter-output>
          </reporter-output>
        </test-method> <!-- test1 -->
        <test-method status="FAIL" signature="test2()[pri:0, instance:tubesRkppl.testNG.KelasA@1aa261b]" name="test2" duration-ms="3" started-at="2014-06-18T10:47:12Z" finished-at="2014-06-18T10:47:12Z">
          <exception class="java.lang.AssertionError">
            <message>
              <![CDATA[seharusnya hasilnya 2 expected [3] but found [2]]]>
            </message>
            <full-stacktrace>
              <![CDATA[java.lang.AssertionError: seharusnya hasilnya 2 expected [3] but found [2]
	at org.testng.Assert.fail(Assert.java:94)
	at org.testng.Assert.failNotSame(Assert.java:490)
	at org.testng.Assert.assertSame(Assert.java:441)
	at tubesRkppl.testNG.KelasA.test2(KelasA.java:24)
	at sun.reflect.NativeMethodAccessorImpl.invoke0(Native Method)
	at sun.reflect.NativeMethodAccessorImpl.invoke(Unknown Source)
	at sun.reflect.DelegatingMethodAccessorImpl.invoke(Unknown Source)
	at java.lang.reflect.Method.invoke(Unknown Source)
	at org.testng.internal.MethodInvocationHelper.invokeMethod(MethodInvocationHelper.java:84)
	at org.testng.internal.Invoker.invokeMethod(Invoker.java:714)
	at org.testng.internal.Invoker.invokeTestMethod(Invoker.java:901)
	at org.testng.internal.Invoker.invokeTestMethods(Invoker.java:1231)
	at org.testng.internal.TestMethodWorker.invokeTestMethods(TestMethodWorker.java:127)
	at org.testng.internal.TestMethodWorker.run(TestMethodWorker.java:111)
	at org.testng.TestRunner.privateRun(TestRunner.java:767)
	at org.testng.TestRunner.run(TestRunner.java:617)
	at org.testng.SuiteRunner.runTest(SuiteRunner.java:334)
	at org.testng.SuiteRunner.runSequentially(SuiteRunner.java:329)
	at org.testng.SuiteRunner.privateRun(SuiteRunner.java:291)
	at org.testng.SuiteRunner.run(SuiteRunner.java:240)
	at org.testng.SuiteRunnerWorker.runSuite(SuiteRunnerWorker.java:52)
	at org.testng.SuiteRunnerWorker.run(SuiteRunnerWorker.java:86)
	at org.testng.TestNG.runSuitesSequentially(TestNG.java:1224)
	at org.testng.TestNG.runSuitesLocally(TestNG.java:1149)
	at org.testng.TestNG.run(TestNG.java:1057)
	at org.testng.remote.RemoteTestNG.run(RemoteTestNG.java:111)
	at org.testng.remote.RemoteTestNG.initAndRun(RemoteTestNG.java:204)
	at org.testng.remote.RemoteTestNG.main(RemoteTestNG.java:175)
]]>
            </full-stacktrace>
          </exception> <!-- java.lang.AssertionError -->
          <reporter-output>
          </reporter-output>
        </test-method> <!-- test2 -->
        <test-method status="PASS" signature="afterTest()[pri:0, instance:tubesRkppl.testNG.KelasA@1aa261b]" name="afterTest" is-config="true" duration-ms="0" started-at="2014-06-18T10:47:12Z" finished-at="2014-06-18T10:47:12Z">
          <reporter-output>
          </reporter-output>
        </test-method> <!-- afterTest -->
      </class> <!-- tubesRkppl.testNG.KelasA -->
    </test> <!-- Default test -->
  </suite> <!-- Default suite -->
</testng-results>
